Workbook

Sheet P&L Statement
A1: HEATRONICS MEDICAL DEVICES PRIVATE LIMITED
A2: Profit & Loss Account | 1-Jul-2026 to 31-Jul-2026 | Amounts in INR
A3: Source: Tally Prime — P&L A/c screen and Group Summary drill-downs (13 screenshots supplied by user, 31-Aug-2026)
A5: Particulars | B5: Amount (INR) | C5: % of Gross Sales | D5: % of Net External Sales | E5: Notes
A6: INCOME
A7: D2C Sales | B7: 1316297.5 | C7: =IF($B$13=0,0,B7/$B$13) -> 0.25039902 | D7: =IF($B$15=0,0,B7/$B$15) -> 0.26989661
A8: Ecommerce Sales | B8: 1196831.3 | C8: =IF($B$13=0,0,B8/$B$13) -> 0.227673 | D8: =IF($B$15=0,0,B8/$B$15) -> 0.245401
A9: OEM Sales | B9: 1895500 | C9: =IF($B$13=0,0,B9/$B$13) -> 0.36058061 | D9: =IF($B$15=0,0,B9/$B$15) -> 0.38865761
A10: Offline Sales | B10: 471081.26 | C10: =IF($B$13=0,0,B10/$B$13) -> 0.089613701 | D10: =IF($B$15=0,0,B10/$B$15) -> 0.096591567
A11: Quick Commerce Sales | B11: -2666.66 | C11: =IF($B$13=0,0,B11/$B$13) -> -0.00050727824 | D11: =IF($B$15=0,0,B11/$B$15) -> -0.000546778 | E11: Net DEBIT — returns/credit notes exceeded sales this month
A12: Stock Transfers (internal) | B12: 379756.14 | C12: =IF($B$13=0,0,B12/$B$13) -> 0.07224094 | D12: =IF($B$15=0,0,B12/$B$15) -> 0.077866058 | E12: Contra — nets off against Purchase Accounts > Stock Transfer
A13: Gross Sales (Tally 'Sales Accounts') | B13: =SUM(B7:B12) -> 5256799.5 | C13: =IF($B$13=0,0,B13/$B$13) -> 1 | D13: =IF($B$15=0,0,B13/$B$15) -> 1.0778661
A14: Less: Internal Stock Transfers | B14: =-B12 -> -379756.14 | C14: =IF($B$13=0,0,B14/$B$13) -> -0.07224094 | D14: =IF($B$15=0,0,B14/$B$15) -> -0.077866058 | E14: Stripped out to show true third-party revenue
A15: NET EXTERNAL SALES | B15: =B13-B12 -> 4877043.4 | C15: =IF($B$13=0,0,B15/$B$13) -> 0.92775906 | D15: =IF($B$15=0,0,B15/$B$15) -> 1
A17: COST OF GOODS SOLD
A18: Opening Stock | B18: 14457824 | C18: =IF($B$13=0,0,B18/$B$13) -> 2.7503092 | D18: =IF($B$15=0,0,B18/$B$15) -> 2.9644649
A19: Purchase Accounts | B19: ='Expense Detail'!B5 -> 1667727.6 | C19: =IF($B$13=0,0,B19/$B$13) -> 0.31725152 | D19: =IF($B$15=0,0,B19/$B$15) -> 0.34195464 | E19: Raw Material 12,86,280.79 + Stock Transfer 3,81,446.84
A20: Direct Expenses | B20: ='Expense Detail'!B8 -> 1094491 | C20: =IF($B$13=0,0,B20/$B$13) -> 0.20820483 | D20: =IF($B$15=0,0,B20/$B$15) -> 0.22441692 | E20: Factory Overheads + Inward Freight + Manufacturing Costs
A21: Less: Closing Stock | B21: =-B18 -> -14457824 | C21: =IF($B$13=0,0,B21/$B$13) -> -2.7503092 | D21: =IF($B$15=0,0,B21/$B$15) -> -2.9644649 | E21: Closing = Opening in Tally — see Ratios & Notes, flag #1
A22: TOTAL COGS | B22: =SUM(B18:B21) -> 2762218.7 | C22: =IF($B$13=0,0,B22/$B$13) -> 0.52545635 | D22: =IF($B$15=0,0,B22/$B$15) -> 0.56637156
A23: GROSS PROFIT | B23: =B13-B22 -> 2494580.9 | C23: =IF($B$13=0,0,B23/$B$13) -> 0.47454365 | D23: =IF($B$15=0,0,B23/$B$15) -> 0.5114945
A25: INDIRECT EXPENSES
A26: Sales & Marketing | B26: ='Expense Detail'!B48 -> 1622149.8 | C26: =IF($B$13=0,0,B26/$B$13) -> 0.30858126 | D26: =IF($B$15=0,0,B26/$B$15) -> 0.33260927
A27: Channel Fees & Commissions | B27: ='Expense Detail'!B19 -> 474617.87 | C27: =IF($B$13=0,0,B27/$B$13) -> 0.09028647 | D27: =IF($B$15=0,0,B27/$B$15) -> 0.097316721
A28: Employee Cost - Indirect (net) | B28: ='Expense Detail'!B41 -> -25887 | C28: =IF($B$13=0,0,B28/$B$13) -> -0.0049244792 | D28: =IF($B$15=0,0,B28/$B$15) -> -0.005307929
A29: Professional Fees | B29: ='Expense Detail'!B47 -> 36000 | C29: =IF($B$13=0,0,B29/$B$13) -> 0.0068482734 | D29: =IF($B$15=0,0,B29/$B$15) -> 0.0073815214
A30: Admin & General Expenses | B30: ='Expense Detail'!B16 -> 22276.42 | C30: =IF($B$13=0,0,B30/$B$13) -> 0.0042376393 | D30: =IF($B$15=0,0,B30/$B$15) -> 0.0045676075
A31: After-Sales & Warranty | B31: ='Expense Detail'!B17 -> 10589.32 | C31: =IF($B$13=0,0,B31/$B$13) -> 0.0020144044 | D31: =IF($B$15=0,0,B31/$B$15) -> 0.0021712581
A32: Staff Welfare | B32: ='Expense Detail'!B54 -> 9370 | C32: =IF($B$13=0,0,B32/$B$13) -> 0.0017824534 | D32: =IF($B$15=0,0,B32/$B$15) -> 0.001921246
A33: Shipping Charges | B33: ='Expense Detail'!B56 -> 5119 | C33: =IF($B$13=0,0,B33/$B$13) -> 0.00097378642 | D33: =IF($B$15=0,0,B33/$B$15) -> 0.0010496113
A34: Freight Outward Exp. - Porter/Transport | B34: ='Expense Detail'!B55 -> 3800 | C34: =IF($B$13=0,0,B34/$B$13) -> 0.0007228733 | D34: =IF($B$15=0,0,B34/$B$15) -> 0.00077916059
A35: Bank Charges | B35: ='Expense Detail'!B18 -> 2575 | C35: =IF($B$13=0,0,B35/$B$13) -> 0.00048984177 | D35: =IF($B$15=0,0,B35/$B$15) -> 0.00052798382
A36: Financial Adjustments (net) | B36: ='Expense Detail'!B44 -> -4.21 | C36: =IF($B$13=0,0,B36/$B$13) -> -8.0086752e-07 | D36: =IF($B$15=0,0,B36/$B$15) -> -8.6322792e-07
A37: TOTAL INDIRECT EXPENSES | B37: =SUM(B26:B36) -> 2160606.2 | C37: =IF($B$13=0,0,B37/$B$13) -> 0.41101172 | D37: =IF($B$15=0,0,B37/$B$15) -> 0.44301559
A38: Add: Indirect Incomes | B38: 5221.53 | C38: =IF($B$13=0,0,B38/$B$13) -> 0.00099329069 | D38: =IF($B$15=0,0,B38/$B$15) -> 0.0010706343
A39: NETT PROFIT | B39: =B23-B37+B38 -> 339196.15 | C39: =IF($B$13=0,0,B39/$B$13) -> 0.064525221 | D39: =IF($B$15=0,0,B39/$B$15) -> 0.069549546
A41: CHECK — Nett Profit shown on Tally P&L screen | B41: 339196.15
A42: Variance (must be 0.00) | B42: =B39-B41 -> 0

Sheet Expense Detail
A1: EXPENSE BREAKDOWN — ALL LEVELS
A2: Heatronics Medical Devices Pvt Ltd | Jul-2026 | Blue = ledger value read from Tally · Black = calculated subtotal
A4: Particulars | B4: Amount (INR) | C4: % of Parent Group | D4: % of Net External Sales | E4: Tally Group
A5: PURCHASE ACCOUNTS | B5: =B6+B7 -> 1667727.6 | C5: 1 | D5: =IF('P&L Statement'!$B$15=0,0,B5/'P&L Statement'!$B$15) -> 0.34195464 | E5: Purchase Accounts
A6: Raw Material Purchases | B6: 1286280.8 | C6: =IF(B5=0,0,B6/B5) -> 0.7712775 | D6: =IF('P&L Statement'!$B$15=0,0,B6/'P&L Statement'!$B$15) -> 0.26374192
A7: Stock Transfer (inward) | B7: 381446.84 | C7: =IF(B5=0,0,B7/B5) -> 0.2287225 | D7: =IF('P&L Statement'!$B$15=0,0,B7/'P&L Statement'!$B$15) -> 0.078212723
A8: DIRECT EXPENSES | B8: =B9+B10+B11 -> 1094491 | C8: 1 | D8: =IF('P&L Statement'!$B$15=0,0,B8/'P&L Statement'!$B$15) -> 0.22441692 | E8: Direct Expenses
A9: Factory Overheads | B9: 395615 | C9: =IF(B8=0,0,B9/B8) -> 0.36146025 | D9: =IF('P&L Statement'!$B$15=0,0,B9/'P&L Statement'!$B$15) -> 0.081117794
A10: Inward Freight | B10: 36584 | C10: =IF(B8=0,0,B10/B8) -> 0.033425582 | D10: =IF('P&L Statement'!$B$15=0,0,B10/'P&L Statement'!$B$15) -> 0.0075012661
A11: Manufacturing Costs | B11: =B12+B13+B14 -> 662292.03 | C11: =IF(B8=0,0,B11/B8) -> 0.60511417 | D11: =IF('P&L Statement'!$B$15=0,0,B11/'P&L Statement'!$B$15) -> 0.13579786
A12: Additional Charges - Purchase | B12: 5788 | C12: =IF(B11=0,0,B12/B11) -> 0.0087393472 | D12: =IF('P&L Statement'!$B$15=0,0,B12/'P&L Statement'!$B$15) -> 0.0011867846
A13: Job Work Charges | B13: 296823.03 | C13: =IF(B11=0,0,B13/B11) -> 0.44817545 | D13: =IF('P&L Statement'!$B$15=0,0,B13/'P&L Statement'!$B$15) -> 0.060861265
A14: Manufacturing Wages | B14: 359681 | C14: =IF(B11=0,0,B14/B11) -> 0.5430852 | D14: =IF('P&L Statement'!$B$15=0,0,B14/'P&L Statement'!$B$15) -> 0.073749806
A15: INDIRECT EXPENSES | B15: =B16+B17+B18+B19+B41+B44+B47+B48+B54+B55+B56 -> 2160606.2 | C15: 1 | D15: =IF('P&L Statement'!$B$15=0,0,B15/'P&L Statement'!$B$15) -> 0.44301559 | E15: Indirect Expenses
A16: Admin & General Expenses | B16: 22276.42 | C16: =IF(B15=0,0,B16/B15) -> 0.010310264 | D16: =IF('P&L Statement'!$B$15=0,0,B16/'P&L Statement'!$B$15) -> 0.0045676075
A17: After-Sales & Warranty | B17: 10589.32 | C17: =IF(B15=0,0,B17/B15) -> 0.0049010874 | D17: =IF('P&L Statement'!$B$15=0,0,B17/'P&L Statement'!$B$15) -> 0.0021712581
A18: Bank Charges | B18: 2575 | C18: =IF(B15=0,0,B18/B15) -> 0.0011917951 | D18: =IF('P&L Statement'!$B$15=0,0,B18/'P&L Statement'!$B$15) -> 0.00052798382
A19: Channel Fees & Commissions | B19: =B20+B31+B32+B40 -> 474617.87 | C19: =IF(B15=0,0,B19/B15) -> 0.21966884 | D19: =IF('P&L Statement'!$B$15=0,0,B19/'P&L Statement'!$B$15) -> 0.097316721
A20: Amazon Channel Fees | B20: =B21+B22+B23+B24+B25+B26+B27+B28+B29+B30 -> 269731.13 | C20: =IF(B19=0,0,B20/B19) -> 0.56831221 | D20: =IF('P&L Statement'!$B$15=0,0,B20/'P&L Statement'!$B$15) -> 0.055306281
A21: FBA Storage Fee - Amazon | B21: 16726.52 | C21: =IF(B20=0,0,B21/B20) -> 0.062011826 | D21: =IF('P&L Statement'!$B$15=0,0,B21/'P&L Statement'!$B$15) -> 0.0034296435
A22: FBA Weight Handling Fee - Amazon | B22: 78649 | C22: =IF(B20=0,0,B22/B20) -> 0.29158296 | D22: =IF('P&L Statement'!$B$15=0,0,B22/'P&L Statement'!$B$15) -> 0.016126369
A23: Fixed Closing Fee - Amazon | B23: 54465.97 | C23: =IF(B20=0,0,B23/B20) -> 0.2019269 | D23: =IF('P&L Statement'!$B$15=0,0,B23/'P&L Statement'!$B$15) -> 0.011167826
A24: Inbound Transportation Fee - Amazon | B24: 3189.19 | C24: =IF(B20=0,0,B24/B20) -> 0.011823589 | D24: =IF('P&L Statement'!$B$15=0,0,B24/'P&L Statement'!$B$15) -> 0.00065391873
A25: Listing Fees - Amazon | B25: 86240.53 | C25: =IF(B20=0,0,B25/B20) -> 0.31972776 | D25: =IF('P&L Statement'!$B$15=0,0,B25/'P&L Statement'!$B$15) -> 0.017682953
A26: Order Cancellation Fee | B26: 1320.36 | C26: =IF(B20=0,0,B26/B20) -> 0.0048950968 | D26: =IF('P&L Statement'!$B$15=0,0,B26/'P&L Statement'!$B$15) -> 0.0002707296
A27: Pick and Pack Fees - Amazon | B27: 15224 | C27: =IF(B20=0,0,B27/B20) -> 0.05644139 | D27: =IF('P&L Statement'!$B$15=0,0,B27/'P&L Statement'!$B$15) -> 0.0031215634
A28: Refund Processing Fee - Amazon | B28: 12350 | C28: =IF(B20=0,0,B28/B20) -> 0.045786335 | D28: =IF('P&L Statement'!$B$15=0,0,B28/'P&L Statement'!$B$15) -> 0.0025322719
A29: Removal Fee - Amazon | B29: 1130 | C29: =IF(B20=0,0,B29/B20) -> 0.004189357 | D29: =IF('P&L Statement'!$B$15=0,0,B29/'P&L Statement'!$B$15) -> 0.00023169776
A30: Shipping Charge Back Fee - Amazon | B30: 435.56 | C30: =IF(B20=0,0,B30/B20) -> 0.0016147932 | D30: =IF('P&L Statement'!$B$15=0,0,B30/'P&L Statement'!$B$15) -> 8.9308207e-05
A31: Blinkit Channel Fees | B31: 8223.93 | C31: =IF(B19=0,0,B31/B19) -> 0.017327477 | D31: =IF('P&L Statement'!$B$15=0,0,B31/'P&L Statement'!$B$15) -> 0.0016862532
A32: D2C Fees | B32: =B33+B34+B35+B39 -> 44101.78 | C32: =IF(B19=0,0,B32/B19) -> 0.092920606 | D32: =IF('P&L Statement'!$B$15=0,0,B32/'P&L Statement'!$B$15) -> 0.0090427287
A33: D2C Checkout | B33: 15014.55 | C33: =IF(B32=0,0,B33/B32) -> 0.34045224 | D33: =IF('P&L Statement'!$B$15=0,0,B33/'P&L Statement'!$B$15) -> 0.0030786173
A34: D2C Communication Fees | B34: 8400 | C34: =IF(B32=0,0,B34/B32) -> 0.1904685 | D34: =IF('P&L Statement'!$B$15=0,0,B34/'P&L Statement'!$B$15) -> 0.001722355
A35: D2C Logistics | B35: =B36+B37+B38 -> 8376.65 | C35: =IF(B32=0,0,B35/B32) -> 0.18993905 | D35: =IF('P&L Statement'!$B$15=0,0,B35/'P&L Statement'!$B$15) -> 0.0017175673
A36: Brand Boost - Shiprocket | B36: 2213.73 | C36: =IF(B35=0,0,B36/B35) -> 0.2642739 | D36: =IF('P&L Statement'!$B$15=0,0,B36/'P&L Statement'!$B$15) -> 0.0004539082
A37: Delivery Boost - Shiprocket | B37: 3796.92 | C37: =IF(B35=0,0,B37/B35) -> 0.45327428 | D37: =IF('P&L Statement'!$B$15=0,0,B37/'P&L Statement'!$B$15) -> 0.00077852906
A38: Shiprocket Generic Fee | B38: 2366 | C38: =IF(B35=0,0,B38/B35) -> 0.28245182 | D38: =IF('P&L Statement'!$B$15=0,0,B38/'P&L Statement'!$B$15) -> 0.00048512999
A39: D2C Payment Gateway | B39: 12310.58 | C39: =IF(B32=0,0,B39/B32) -> 0.27914021 | D39: =IF('P&L Statement'!$B$15=0,0,B39/'P&L Statement'!$B$15) -> 0.0025241892
A40: Freight Charges (Shiprocket) | B40: 152561.03 | C40: =IF(B19=0,0,B40/B19) -> 0.32143971 | D40: =IF('P&L Statement'!$B$15=0,0,B40/'P&L Statement'!$B$15) -> 0.031281459
A41: Employee Cost - Indirect (net) | B41: =B42+B43 -> -25887 | C41: =IF(B15=0,0,B41/B15) -> -0.01198136 | D41: =IF('P&L Statement'!$B$15=0,0,B41/'P&L Statement'!$B$15) -> -0.005307929
...

Sheet Revenue Detail
A1: REVENUE BY CHANNEL — WITH DIRECT CHANNEL COSTS
A2: Jul-2026 | Tally Group Summary > Sales Accounts
A4: Channel | B4: Revenue (INR) | C4: % of Gross Sales | D4: Marketing + Channel Fees (INR) | E4: Cost as % of channel revenue | F4: Contribution after direct channel cost | G4: What is included
A5: OEM Sales | B5: 1895500 | C5: =IF($B$11=0,0,B5/$B$11) -> 0.36058061 | G5: No channel-specific marketing or platform fee tagged in Tally
A6: D2C Sales | B6: 1316297.5 | C6: =IF($B$11=0,0,B6/$B$11) -> 0.25039902 | D6: ='Expense Detail'!B49+'Expense Detail'!B32 -> 1052961.5 | E6: =IF(B6<=0,"n/m",D6/B6) -> 0.79994189 | F6: =B6-D6 -> 263335.98 | G6: D2C Marketing 10,08,859.70 + D2C Fees 44,101.78 (checkout, comms, logistics, payment gateway)
A7: Ecommerce Sales | B7: 1196831.3 | C7: =IF($B$11=0,0,B7/$B$11) -> 0.227673 | D7: ='Expense Detail'!B53+'Expense Detail'!B20 -> 883021.26 | E7: =IF(B7<=0,"n/m",D7/B7) -> 0.73779926 | F7: =B7-D7 -> 313810.05 | G7: Ecommerce Marketing 6,13,290.13 + Amazon Channel Fees 2,69,731.13
A8: Offline Sales | B8: 471081.26 | C8: =IF($B$11=0,0,B8/$B$11) -> 0.089613701 | G8: No channel-specific cost tagged
A9: Quick Commerce Sales | B9: -2666.66 | C9: =IF($B$11=0,0,B9/$B$11) -> -0.00050727824 | D9: ='Expense Detail'!B31 -> 8223.93 | E9: =IF(B9<=0,"n/m",D9/B9) -> n/m | F9: =B9-D9 -> -10890.59 | G9: Blinkit Channel Fees 8,223.93 — incurred despite net negative sales
A10: Stock Transfers (internal) | B10: 379756.14 | C10: =IF($B$11=0,0,B10/$B$11) -> 0.07224094 | G10: Contra entry — not third-party revenue
A11: GROSS SALES | B11: =SUM(B5:B10) -> 5256799.5 | D11: =SUM(D5:D10) -> 1944206.7
A12: NET EXTERNAL SALES (excl. internal stock transfers) | B12: =B11-B10 -> 4877043.4

Sheet Ratios & Notes
A1: KEY RATIOS — JUL 2026
A3: Metric | B3: Value | C3: Basis / comment
A4: Gross Sales | B4: ='P&L Statement'!B13 -> 5256799.5 | C4: Tally 'Sales Accounts' total
A5: Net External Sales | B5: ='P&L Statement'!B15 -> 4877043.4 | C5: Gross sales less internal stock transfers of 3,79,756.14
A6: Gross Profit | B6: ='P&L Statement'!B23 -> 2494580.9 | C6: Per Tally P&L — but see flag #1
A7: Gross Margin % (on gross sales) | B7: ='P&L Statement'!B23/'P&L Statement'!B13 -> 0.47454365
A8: Gross Margin % (on net external sales) | B8: ='P&L Statement'!B23/'P&L Statement'!B15 -> 0.5114945
A9: Total Indirect Expenses | B9: ='P&L Statement'!B37 -> 2160606.2
A10: Indirect Expenses as % of net external sales | B10: ='P&L Statement'!B37/'P&L Statement'!B15 -> 0.44301559 | C10: Operating overhead load
A11: Nett Profit | B11: ='P&L Statement'!B39 -> 339196.15
A12: Net Margin % (on net external sales) | B12: ='P&L Statement'!B39/'P&L Statement'!B15 -> 0.069549546
A14: Total Marketing Spend | B14: ='Expense Detail'!B48 -> 1622149.8 | C14: Sales & Marketing group
A15: Marketing as % of net external sales | B15: ='Expense Detail'!B48/'P&L Statement'!B15 -> 0.33260927 | C15: Single largest cost line in the business this month
A16: D2C Marketing spend | B16: ='Expense Detail'!B49 -> 1008859.7 | C16: Google 1,32,224.20 + Agency 1,80,000.00 + Meta 6,96,635.50
A17: D2C Marketing as % of D2C sales | B17: ='Expense Detail'!B49/'Revenue Detail'!B6 -> 0.76643747 | C17: Ad cost per rupee of D2C revenue
A18: D2C blended MER (revenue per Re of ad spend) | B18: ='Revenue Detail'!B6/'Expense Detail'!B49 -> 1.3047379 | C18: Below ~2.5x usually means D2C is losing money after COGS
A19: Ecommerce Marketing spend | B19: ='Expense Detail'!B53 -> 613290.13
A20: Ecommerce Marketing as % of Ecommerce sales | B20: ='Expense Detail'!B53/'Revenue Detail'!B7 -> 0.51242821
A21: Ecommerce blended MER | B21: ='Revenue Detail'!B7/'Expense Detail'!B53 -> 1.9514929
A23: Total Channel Fees & Commissions | B23: ='Expense Detail'!B19 -> 474617.87
A24: Channel fees as % of net external sales | B24: ='Expense Detail'!B19/'P&L Statement'!B15 -> 0.097316721
A25: Amazon fees as % of Ecommerce sales | B25: ='Expense Detail'!B20/'Revenue Detail'!B7 -> 0.22537105 | C25: Platform take rate on Amazon
A26: Total Shiprocket cost | B26: ='Expense Detail'!B40+'Expense Detail'!B36+'Expense Detail'!B37+'Expense Detail'!B38 -> 160937.68 | C26: Freight 1,52,561.03 + Brand Boost + Delivery Boost + generic fee
A27: Shiprocket cost as % of D2C sales | B27: =('Expense Detail'!B40+'Expense Detail'!B36+'Expense Detail'!B37+'Expense Detail'!B38)/'Revenue Detail'!B6 -> 0.12226543 | C27: Assumes Shiprocket freight is D2C-driven
A29: OEM sales as % of net external sales | B29: ='Revenue Detail'!B5/'P&L Statement'!B15 -> 0.38865761 | C29: Largest single revenue line, with no tagged channel cost
A30: D2C + Ecommerce as % of net external sales | B30: =('Revenue Detail'!B6+'Revenue Detail'!B7)/'P&L Statement'!B15 -> 0.51529761
A31: Total variable channel cost (marketing + channel fees) | B31: ='Expense Detail'!B48+'Expense Detail'!B19 -> 2096767.7
A32: … as % of D2C + Ecommerce sales | B32: =('Expense Detail'!B48+'Expense Detail'!B19)/('Revenue Detail'!B6+'Revenue Detail'!B7) -> 0.83432561 | C32: The number that decides whether online is profitable
A35: NOTES, ASSUMPTIONS & FLAGS
A37: FLAG 1 — Opening Stock equals Closing Stock (1,44,57,824.00)
A38: Tally shows identical opening and closing inventory, so stock movement contributes exactly ZERO to cost of goods sold this month. Either July stock was never re-valued in Tally, or closing stock was entered manually equal to opening. Until that is fixed, the 24,94,580.85 'Gross Profit' is really just Sales less Purchases less Direct Expenses — not a true gross margin. Every margin percentage in this workbook inherits that caveat.
A40: FLAG 2 — Employee Cost - Indirect carries both a debit and a credit
A41: Debit 4,19,204.00 and credit 4,45,091.00, netting to a CREDIT of 25,887.00 — i.e. negative employee cost for July. This is the only reading under which the group figures foot to the 21,60,606.23 indirect-expense total on the P&L screen. Almost certainly a reversal, a provision write-back, or a wrongly-signed entry. Worth checking before this month is filed.
A43: FLAG 3 — Financial Adjustments nets to a credit of 4.21
A44: Debit 0.03, credit 4.24. Rounding-level, no action needed.
A46: FLAG 4 — Stock Transfers appear on both sides of the P&L
A47: Sales Accounts > Stock Transfers 3,79,756.14 (credit) and Purchase Accounts > Stock Transfer 3,81,446.84 (debit). These are internal movements, not third-party trade. Net P&L impact of the pair is a 1,690.70 debit. 'Net External Sales' in this workbook strips the sales-side transfer out so channel ratios are not flattered.
A49: FLAG 5 — Quick Commerce Sales is a net DEBIT of 2,666.66
A50: Returns and credit notes exceeded gross sales on quick commerce in July, while Blinkit channel fees of 8,223.93 were still incurred. Small in absolute terms but the channel lost money outright.
A52: FLAG 6 — Freight Charges (Shiprocket) is grouped under Channel Fees, not D2C Logistics
...
